# Import necessary libraries and modules for testing
import asyncio
from unittest.mock import AsyncMock, patch

# Import the module to be tested
import bot

# Pytest library for testing
import pytest

# Test the process_input_message function for various scenarios
class TestProcessInputMessage:
    # Test processing a normal message
    @pytest.mark.asyncio
    async def test_process_normal_message(self):
        # Mock dependencies
        with patch('bot.OpenAI') as mock_openai, \
             patch('bot.get_conversation_summary', return_value=[]), \
             patch('bot.logger') as mock_logger:
            # Setup mock OpenAI client response
            mock_openai_client = AsyncMock()
            mock_openai_client.chat.completions.create.return_value = AsyncMock(choices=[AsyncMock(message=AsyncMock(content="Test response"))])
            mock_openai.return_value = mock_openai_client

            # Mock user and input message
            mock_user = AsyncMock()
            mock_user.id = 123
            input_message = "Hello"

            # Call the function under test
            response = await bot.process_input_message(input_message, mock_user, [])

            # Assert the response is as expected
            assert response == "Test response"
            # Assert logging calls
            mock_logger.info.assert_called_with("Received response from OpenAI API.")

    # Test processing a message when OpenAI API returns no choices
    @pytest.mark.asyncio
    async def test_process_message_no_response(self):
        # Mock dependencies
        with patch('bot.OpenAI') as mock_openai, \
             patch('bot.get_conversation_summary', return_value=[]), \
             patch('bot.logger') as mock_logger:
            # Setup mock OpenAI client response with no choices
            mock_openai_client = AsyncMock()
            mock_openai_client.chat.completions.create.return_value = AsyncMock(choices=[])
            mock_openai.return_value = mock_openai_client

            # Mock user and input message
            mock_user = AsyncMock()
            mock_user.id = 123
            input_message = "Hello"

            # Call the function under test
            response = await bot.process_input_message(input_message, mock_user, [])

            # Assert the response indicates an error
            assert response == "Sorry, I didn't get that. Can you rephrase or ask again?"
            # Assert logging calls
            mock_logger.error.assert_called_with("OpenAI API error: No response text.")

    # Test processing a message when an exception occurs
    @pytest.mark.asyncio
    async def test_process_message_exception(self):
        # Mock dependencies to raise an exception
        with patch('bot.OpenAI') as mock_openai, \
             patch('bot.get_conversation_summary', return_value=[]), \
             patch('bot.logger') as mock_logger:
            # Setup mock OpenAI client to raise an exception
            mock_openai_client = AsyncMock()
            mock_openai_client.chat.completions.create.side_effect = Exception("Test exception")
            mock_openai.return_value = mock_openai_client

            # Mock user and input message
            mock_user = AsyncMock()
            mock_user.id = 123
            input_message = "Hello"

            # Call the function under test
            response = await bot.process_input_message(input_message, mock_user, [])

            # Assert the response indicates an error
            assert response == "An error occurred while processing the message."
            # Assert logging calls
            mock_logger.error.assert_called_with("An error processing message: Test exception")

# Explanation of what the tests are testing for:
# 1. `test_process_normal_message`: Tests that a normal input message is processed correctly and returns the expected response from the OpenAI API.
# 2. `test_process_message_no_response`: Tests the function's behavior when the OpenAI API returns an empty list of choices, simulating no response.
# 3. `test_process_message_exception`: Tests how the function handles exceptions, such as network errors or unexpected issues with the OpenAI API.